                                          
[06-Sep-25 10:19:32 - INFO] - aiohttp.access - 172.31.77.194 [06/Sep/2025:10:19:32 +0000] "GET / HTTP/1.1" 200 178 "https://1005ec4c-1b6b-4486-9fbc-72b6e11a82bb-00-3757v57maq7g7.pike.replit.dev/__replco/workspace_iframe.html?initialPath=%2F&id=%3Ar184%3A" "Mozilla/5.0 (Windows NT 10.0; Win64; x64) AppleWebKit/537.36 (KHTML, like Gecko) Chrome/139.0.0.0 Safari/537.36"
[06-Sep-25 10:19:51 - ERROR] - pyrogram.dispatcher - cannot access local variable 'asyncio' where it is not associated with a value
Traceback (most recent call last):
  File "/home/runner/workspace/.pythonlibs/lib/python3.11/site-packages/pyrogram/dispatcher.py", line 242, in handler_worker
    await self.loop.run_in_executor(
  File "/nix/store/7d088dip86hlzri9sk0h78b63yfmx0a0-python3-3.11.13/lib/python3.11/concurrent/futures/thread.py", line 58, in run
    result = self.fn(*self.args, **self.kwargs)
             ^^^^^^^^^^^^^^^^^^^^^^^^^^^^^^^^^^
  File "/home/runner/workspace/.pythonlibs/lib/python3.11/site-packages/pyrogram/sync.py", line 78, in async_to_sync_wrap
    return asyncio.run_coroutine_threadsafe(coroutine, main_loop).result()
           ^^^^^^^^^^^^^^^^^^^^^^^^^^^^^^^^^^^^^^^^^^^^^^^^^^^^^^^^^^^^^^^
  File "/nix/store/7d088dip86hlzri9sk0h78b63yfmx0a0-python3-3.11.13/lib/python3.11/concurrent/futures/_base.py", line 456, in result
    return self.__get_result()
           ^^^^^^^^^^^^^^^^^^^
  File "/nix/store/7d088dip86hlzri9sk0h78b63yfmx0a0-python3-3.11.13/lib/python3.11/concurrent/futures/_base.py", line 401, in __get_result
    raise self._exception
  File "/home/runner/workspace/.pythonlibs/lib/python3.11/site-packages/pyromod/listen/message_handler.py", line 98, in resolve_future_or_callback
    await self.original_callback(client, message, *args)
  File "/home/runner/workspace/plugins/start.py", line 39, in start_handler
    await asyncio.sleep(2)
          ^^^^^^^
UnboundLocalError: cannot access local variable 'asyncio' where it is not associated with a value
