Pyromod is working! If you like pyromod, please star it at https://github.com/usernein/pyromod
[07-Sep-25 16:09:56 - INFO] - bot - Bot Running..!

Created by 
https://t.me/ultroid_official
[07-Sep-25 16:09:56 - INFO] - bot -  

       
(っ◔◡◔)っ ♥ ULTROIDOFFICIAL ♥
░╚════╝░░╚════╝░╚═════╝░╚══════╝
                                          
[07-Sep-25 16:09:59 - INFO] - bot - ==================================================
[07-Sep-25 16:09:59 - INFO] - bot - 📊 VERIFICATION STATISTICS (Last 24 Hours)
[07-Sep-25 16:09:59 - INFO] - bot - ==================================================
[07-Sep-25 16:09:59 - INFO] - bot - ✅ Total Active Verified Users: 4
[07-Sep-25 16:09:59 - INFO] - bot - 🆕 New Verifications (24h): 4
[07-Sep-25 16:09:59 - INFO] - bot - 
🔔 Recent Verifications:
[07-Sep-25 16:09:59 - INFO] - bot -   1. 👤 Ritvik (@kvg_ritvik)
     🆔 ID: 7066408742
     ⏰ Verified: 2025-09-06 16:45:42
     ⏳ Expires in: 0h 35m
[07-Sep-25 16:09:59 - INFO] - bot -   2. 👤 Jn (No username)
     🆔 ID: 8077775478
     ⏰ Verified: 2025-09-07 13:50:23
     ⏳ Expires in: 21h 40m
[07-Sep-25 16:09:59 - INFO] - bot -   3. 👤 Crazy01 (No username)
     🆔 ID: 6192345811
     ⏰ Verified: 2025-09-06 20:40:49
     ⏳ Expires in: 4h 30m
[07-Sep-25 16:10:00 - INFO] - bot -   4. 👤 Jack (@Jacksparwking)
     🆔 ID: 7623389594
     ⏰ Verified: 2025-09-07 14:04:37
     ⏳ Expires in: 21h 54m
[07-Sep-25 16:10:00 - INFO] - bot - ==================================================
[07-Sep-25 16:11:32 - ERROR] - pyrogram.dispatcher - name 'user_data' is not defined
Traceback (most recent call last):
  File "/home/runner/workspace/.pythonlibs/lib/python3.12/site-packages/pyrogram/dispatcher.py", line 242, in handler_worker
    await self.loop.run_in_executor(
  File "/nix/store/vnvdzw4182wb2ifzi0cczhv80yfnpx1q-python3-3.12.11/lib/python3.12/concurrent/futures/thread.py", line 59, in run
    result = self.fn(*self.args, **self.kwargs)
             ^^^^^^^^^^^^^^^^^^^^^^^^^^^^^^^^^^
  File "/home/runner/workspace/.pythonlibs/lib/python3.12/site-packages/pyrogram/sync.py", line 78, in async_to_sync_wrap
    return asyncio.run_coroutine_threadsafe(coroutine, main_loop).result()
           ^^^^^^^^^^^^^^^^^^^^^^^^^^^^^^^^^^^^^^^^^^^^^^^^^^^^^^^^^^^^^^^
  File "/nix/store/vnvdzw4182wb2ifzi0cczhv80yfnpx1q-python3-3.12.11/lib/python3.12/concurrent/futures/_base.py", line 456, in result
    return self.__get_result()
           ^^^^^^^^^^^^^^^^^^^
  File "/nix/store/vnvdzw4182wb2ifzi0cczhv80yfnpx1q-python3-3.12.11/lib/python3.12/concurrent/futures/_base.py", line 401, in __get_result
    raise self._exception
  File "/home/runner/workspace/.pythonlibs/lib/python3.12/site-packages/pyromod/listen/message_handler.py", line 98, in resolve_future_or_callback
    await self.original_callback(client, message, *args)
  File "/home/runner/workspace/plugins/start.py", line 129, in start_handler
    user_doc = await user_data.find_one({'_id': user_id})
                     ^^^^^^^^^
NameError: name 'user_data' is not defined
